Workbook
Name Slicer_Representative: #N/A

Sheet Pivots
A3: Call Count | B3: Total Amount | C3: Total Duration | D3: Avg Rating | E3: 5* Calls
A4: 1000 | B4: 96623 | C4: 89850 | D4: 3.8854 | E4: 307
A9: Call Count | B9: Total Amount | C9: Total Duration | D9: Avg Rating | E9: 5* Calls
A10: 207 | B10: 20872 | C10: 17700 | D10: 3.8589372 | E10: 60
A20: Row Labels | B20: Call Count | C20: Call Count2 | F20: Row Labels | G20: Call Count
A21: Jan | B21: 13 | C21: 13 | F21: Sunday | G21: 30
A22: Feb | B22: 13 | C22: 13 | F22: Monday | G22: 34
A23: Mar | B23: 28 | C23: 28 | F23: Tuesday | G23: 26
A24: Apr | B24: 24 | C24: 24 | F24: Wednesday | G24: 38
A25: May | B25: 23 | C25: 23 | F25: Thursday | G25: 27
A26: Jun | B26: 17 | C26: 17 | F26: Friday | G26: 27
A27: Jul | B27: 11 | C27: 11 | F27: Saturday | G27: 25
A28: Aug | B28: 11 | C28: 11 | F28: Grand Total | G28: 207
A29: Sep | B29: 14 | C29: 14
A30: Oct | B30: 30 | C30: 30
A31: Nov | B31: 14 | C31: 14
A32: Dec | B32: 9 | C32: 9
A33: Grand Total | B33: 207 | C33: 207
F38: For Graph | I38: Selected rep | J38: =A51 -> R03
A40: Row Labels | B40: Call Count | C40: Total Amount | F40: Rep | G40: Calls | H40: Amount | I40: Sel. Calls | J40: Sel.Amount
A41: R01 | B41: 189 | C41: 18415 | F41: =A41 -> R01 | G41: =B41 -> 189 | H41: =C41 -> 18415 | I41: =IF(F41=$J$38, G41, NA()) -> #N/A | J41: =IF(F41=$J$38, H41, NA()) -> #N/A
A42: R02 | B42: 218 | C42: 20581 | F42: =A42 -> R02 | G42: =B42 -> 218 | H42: =C42 -> 20581 | I42: =IF(F42=$J$38, G42, NA()) -> #N/A | J42: =IF(F42=$J$38, H42, NA()) -> #N/A
A43: R03 | B43: 207 | C43: 20872 | F43: =A43 -> R03 | G43: =B43 -> 207 | H43: =C43 -> 20872 | I43: =IF(F43=$J$38, G43, NA()) -> 207 | J43: =IF(F43=$J$38, H43, NA()) -> 20872
A44: R04 | B44: 186 | C44: 16651 | F44: =A44 -> R04 | G44: =B44 -> 186 | H44: =C44 -> 16651 | I44: =IF(F44=$J$38, G44, NA()) -> #N/A | J44: =IF(F44=$J$38, H44, NA()) -> #N/A
A45: R05 | B45: 200 | C45: 20104 | F45: =A45 -> R05 | G45: =B45 -> 200 | H45: =C45 -> 20104 | I45: =IF(F45=$J$38, G45, NA()) -> #N/A | J45: =IF(F45=$J$38, H45, NA()) -> #N/A
A46: Grand Total | B46: 1000 | C46: 96623
A50: Row Labels
A51: R03
A60: Count of Call number | B60: Column Labels
A61: Row Labels | B61: Female | C61: Male | D61: Grand Total
A62: Cincinnati | B62: 144 | C62: 132 | D62: 276
A63: Cleveland | B63: 326 | C63: 63 | D63: 389
A64: Columbus | B64: 129 | C64: 206 | D64: 335
A65: Grand Total | B65: 599 | C65: 401 | D65: 1000
A71: Row Labels | B71: Count of Call number
A72: 2 | B72: 11
A73: 3 | B73: 46
A74: 4 | B74: 88
A75: 5 | B75: 60
A76: 1 | B76: 1
...

Sheet Data
B1: Call Centre Data
B3: Call number | C3: Customer ID | D3: Duration | E3: Representative | F3: Date of Call | G3: Purchase Amount | H3: Satisfaction Rating | I3: FY | J3: Day of week | K3: Duration Bucket | L3: Rating rounded | Q3: Customer ID | R3: Gedner | S3: Age | T3: City
B4: Call_7271 | C4: C0003 | D4: 116 | E4: R05 | F4: 44927 | G4: 128 | H4: 4.9 | I4: =IF(MONTH(calls[[#This Row],[Date of Call]])<=6, YEAR(calls[[#This Row],[Date of Call]]), YEAR(calls[[#This Row],[Date of Call]])+1) -> 2023 | J4: =TEXT(calls[[#This Row],[Date of Call]],"DDDD") -> Sunday | K4: {=_xlfn.IFS(calls[[#This Row],[Duration]]<=10,"Under 10 mins", calls[[#This Row],[Duration]]<=30, "10 to 30 mins", calls[[#This Row],[Duration]]<=60, "30 to 60 mins", calls[[#This Row],[Duration]]<=120, "1 to 2 hours", TRUE, "More than 2 hours")} -> 1 to 2 hours | L4: =ROUND(calls[[#This Row],[Satisfaction Rating]],0) -> 5 | Q4: C0001 | R4: Male | S4: 41 | T4: Columbus
B5: Call_7272 | C5: C0004 | D5: 119 | E5: R05 | F5: 44927 | G5: 135 | H5: 2.9 | I5: =IF(MONTH(calls[[#This Row],[Date of Call]])<=6, YEAR(calls[[#This Row],[Date of Call]]), YEAR(calls[[#This Row],[Date of Call]])+1) -> 2023 | J5: =TEXT(calls[[#This Row],[Date of Call]],"DDDD") -> Sunday | K5: {=_xlfn.IFS(calls[[#This Row],[Duration]]<=10,"Under 10 mins", calls[[#This Row],[Duration]]<=30, "10 to 30 mins", calls[[#This Row],[Duration]]<=60, "30 to 60 mins", calls[[#This Row],[Duration]]<=120, "1 to 2 hours", TRUE, "More than 2 hours")} -> 1 to 2 hours | L5: =ROUND(calls[[#This Row],[Satisfaction Rating]],0) -> 3 | Q5: C0002 | R5: Male | S5: 31 | T5: Cleveland
B6: Call_7273 | C6: C0005 | D6: 68 | E6: R02 | F6: 44927 | G6: 66 | H6: 4.7 | I6: =IF(MONTH(calls[[#This Row],[Date of Call]])<=6, YEAR(calls[[#This Row],[Date of Call]]), YEAR(calls[[#This Row],[Date of Call]])+1) -> 2023 | J6: =TEXT(calls[[#This Row],[Date of Call]],"DDDD") -> Sunday | K6: {=_xlfn.IFS(calls[[#This Row],[Duration]]<=10,"Under 10 mins", calls[[#This Row],[Duration]]<=30, "10 to 30 mins", calls[[#This Row],[Duration]]<=60, "30 to 60 mins", calls[[#This Row],[Duration]]<=120, "1 to 2 hours", TRUE, "More than 2 hours")} -> 1 to 2 hours | L6: =ROUND(calls[[#This Row],[Satisfaction Rating]],0) -> 5 | Q6: C0003 | R6: Male | S6: 26 | T6: Cincinnati
B7: Call_7274 | C7: C0014 | D7: 119 | E7: R02 | F7: 44927 | G7: 22 | H7: 2.9 | I7: =IF(MONTH(calls[[#This Row],[Date of Call]])<=6, YEAR(calls[[#This Row],[Date of Call]]), YEAR(calls[[#This Row],[Date of Call]])+1) -> 2023 | J7: =TEXT(calls[[#This Row],[Date of Call]],"DDDD") -> Sunday | K7: {=_xlfn.IFS(calls[[#This Row],[Duration]]<=10,"Under 10 mins", calls[[#This Row],[Duration]]<=30, "10 to 30 mins", calls[[#This Row],[Duration]]<=60, "30 to 60 mins", calls[[#This Row],[Duration]]<=120, "1 to 2 hours", TRUE, "More than 2 hours")} -> 1 to 2 hours | L7: =ROUND(calls[[#This Row],[Satisfaction Rating]],0) -> 3 | Q7: C0004 | R7: Male | S7: 36 | T7: Cincinnati
B8: Call_7275 | C8: C0011 | D8: 128 | E8: R01 | F8: 44928 | G8: 31 | H8: 2.8 | I8: =IF(MONTH(calls[[#This Row],[Date of Call]])<=6, YEAR(calls[[#This Row],[Date of Call]]), YEAR(calls[[#This Row],[Date of Call]])+1) -> 2023 | J8: =TEXT(calls[[#This Row],[Date of Call]],"DDDD") -> Monday | K8: {=_xlfn.IFS(calls[[#This Row],[Duration]]<=10,"Under 10 mins", calls[[#This Row],[Duration]]<=30, "10 to 30 mins", calls[[#This Row],[Duration]]<=60, "30 to 60 mins", calls[[#This Row],[Duration]]<=120, "1 to 2 hours", TRUE, "More than 2 hours")} -> More than 2 hours | L8: =ROUND(calls[[#This Row],[Satisfaction Rating]],0) -> 3 | Q8: C0005 | R8: Male | S8: 37 | T8: Columbus
B9: Call_7276 | C9: C0011 | D9: 49 | E9: R02 | F9: 44929 | G9: 135 | H9: 4.8 | I9: =IF(MONTH(calls[[#This Row],[Date of Call]])<=6, YEAR(calls[[#This Row],[Date of Call]]), YEAR(calls[[#This Row],[Date of Call]])+1) -> 2023 | J9: =TEXT(calls[[#This Row],[Date of Call]],"DDDD") -> Tuesday | K9: {=_xlfn.IFS(calls[[#This Row],[Duration]]<=10,"Under 10 mins", calls[[#This Row],[Duration]]<=30, "10 to 30 mins", calls[[#This Row],[Duration]]<=60, "30 to 60 mins", calls[[#This Row],[Duration]]<=120, "1 to 2 hours", TRUE, "More than 2 hours")} -> 30 to 60 mins | L9: =ROUND(calls[[#This Row],[Satisfaction Rating]],0) -> 5 | Q9: C0006 | R9: Male | S9: 23 | T9: Columbus
B10: Call_7277 | C10: C0007 | D10: 84 | E10: R05 | F10: 44929 | G10: 60 | H10: 4.7 | I10: =IF(MONTH(calls[[#This Row],[Date of Call]])<=6, YEAR(calls[[#This Row],[Date of Call]]), YEAR(calls[[#This Row],[Date of Call]])+1) -> 2023 | J10: =TEXT(calls[[#This Row],[Date of Call]],"DDDD") -> Tuesday | K10: {=_xlfn.IFS(calls[[#This Row],[Duration]]<=10,"Under 10 mins", calls[[#This Row],[Duration]]<=30, "10 to 30 mins", calls[[#This Row],[Duration]]<=60, "30 to 60 mins", calls[[#This Row],[Duration]]<=120, "1 to 2 hours", TRUE, "More than 2 hours")} -> 1 to 2 hours | L10: =ROUND(calls[[#This Row],[Satisfaction Rating]],0) -> 5 | Q10: C0007 | R10: Female | S10: 22 | T10: Cleveland
B11: Call_7278 | C11: C0003 | D11: 103 | E11: R04 | F11: 44929 | G11: 148 | H11: 4.4 | I11: =IF(MONTH(calls[[#This Row],[Date of Call]])<=6, YEAR(calls[[#This Row],[Date of Call]]), YEAR(calls[[#This Row],[Date of Call]])+1) -> 2023 | J11: =TEXT(calls[[#This Row],[Date of Call]],"DDDD") -> Tuesday | K11: {=_xlfn.IFS(calls[[#This Row],[Duration]]<=10,"Under 10 mins", calls[[#This Row],[Duration]]<=30, "10 to 30 mins", calls[[#This Row],[Duration]]<=60, "30 to 60 mins", calls[[#This Row],[Duration]]<=120, "1 to 2 hours", TRUE, "More than 2 hours")} -> 1 to 2 hours | L11: =ROUND(calls[[#This Row],[Satisfaction Rating]],0) -> 4 | Q11: C0008 | R11: Female | S11: 42 | T11: Cleveland
B12: Call_7279 | C12: C0005 | D12: 31 | E12: R02 | F12: 44929 | G12: 135 | H12: 3.6 | I12: =IF(MONTH(calls[[#This Row],[Date of Call]])<=6, YEAR(calls[[#This Row],[Date of Call]]), YEAR(calls[[#This Row],[Date of Call]])+1) -> 2023 | J12: =TEXT(calls[[#This Row],[Date of Call]],"DDDD") -> Tuesday | K12: {=_xlfn.IFS(calls[[#This Row],[Duration]]<=10,"Under 10 mins", calls[[#This Row],[Duration]]<=30, "10 to 30 mins", calls[[#This Row],[Duration]]<=60, "30 to 60 mins", calls[[#This Row],[Duration]]<=120, "1 to 2 hours", TRUE, "More than 2 hours")} -> 30 to 60 mins | L12: =ROUND(calls[[#This Row],[Satisfaction Rating]],0) -> 4 | Q12: C0009 | R12: Female | S12: 25 | T12: Columbus
B13: Call_7280 | C13: C0010 | D13: 44 | E13: R03 | F13: 44929 | G13: 105 | H13: 2.9 | I13: =IF(MONTH(calls[[#This Row],[Date of Call]])<=6, YEAR(calls[[#This Row],[Date of Call]]), YEAR(calls[[#This Row],[Date of Call]])+1) -> 2023 | J13: =TEXT(calls[[#This Row],[Date of Call]],"DDDD") -> Tuesday | K13: {=_xlfn.IFS(calls[[#This Row],[Duration]]<=10,"Under 10 mins", calls[[#This Row],[Duration]]<=30, "10 to 30 mins", calls[[#This Row],[Duration]]<=60, "30 to 60 mins", calls[[#This Row],[Duration]]<=120, "1 to 2 hours", TRUE, "More than 2 hours")} -> 30 to 60 mins | L13: =ROUND(calls[[#This Row],[Satisfaction Rating]],0) -> 3 | Q13: C0010 | R13: Female | S13: 30 | T13: Cleveland
B14: Call_7281 | C14: C0011 | D14: 102 | E14: R02 | F14: 44929 | G14: 69 | H14: 4.9 | I14: =IF(MONTH(calls[[#This Row],[Date of Call]])<=6, YEAR(calls[[#This Row],[Date of Call]]), YEAR(calls[[#This Row],[Date of Call]])+1) -> 2023 | J14: =TEXT(calls[[#This Row],[Date of Call]],"DDDD") -> Tuesday | K14: {=_xlfn.IFS(calls[[#This Row],[Duration]]<=10,"Under 10 mins", calls[[#This Row],[Duration]]<=30, "10 to 30 mins", calls[[#This Row],[Duration]]<=60, "30 to 60 mins", calls[[#This Row],[Duration]]<=120, "1 to 2 hours", TRUE, "More than 2 hours")} -> 1 to 2 hours | L14: =ROUND(calls[[#This Row],[Satisfaction Rating]],0) -> 5 | Q14: C0011 | R14: Female | S14: 30 | T14: Cincinnati
B15: Call_7282 | C15: C0013 | D15: 135 | E15: R05 | F15: 44929 | G15: 46 | H15: 3.4 | I15: =IF(MONTH(calls[[#This Row],[Date of Call]])<=6, YEAR(calls[[#This Row],[Date of Call]]), YEAR(calls[[#This Row],[Date of Call]])+1) -> 2023 | J15: =TEXT(calls[[#This Row],[Date of Call]],"DDDD") -> Tuesday | K15: {=_xlfn.IFS(calls[[#This Row],[Duration]]<=10,"Under 10 mins", calls[[#This Row],[Duration]]<=30, "10 to 30 mins", calls[[#This Row],[Duration]]<=60, "30 to 60 mins", calls[[#This Row],[Duration]]<=120, "1 to 2 hours", TRUE, "More than 2 hours")} -> More than 2 hours | L15: =ROUND(calls[[#This Row],[Satisfaction Rating]],0) -> 3 | Q15: C0012 | R15: Female | S15: 28 | T15: Cincinnati
... B18: Call_7285 | C18: C0013 | D18: 48 | E18: R01 | F18: 44930 | G18: 68 | H18: 4.9 | I18: =IF(MONTH(calls[[#This Row],[Date of Call]])<=6, YEAR(calls[[#This Row],[Date of Call]]), YEAR(calls[[#This Row],[Date of Call]])+1) -> 2023 | J18: =TEXT(calls[[#This Row],[Date of Call]],"DDDD") -> Wednesday | K18: {=_xlfn.IFS(calls[[#This Row],[Duration]]<=10,"Under 10 mins", calls[[#This Row],[Duration]]<=30, "10 to 30 mins", calls[[#This Row],[Duration]]<=60, "30 to 60 mins", calls[[#This Row],[Duration]]<=120, "1 to 2 hours", TRUE, "More than 2 hours")} -> 30 to 60 mins | L18: =ROUND(calls[[#This Row],[Satisfaction Rating]],0) -> 5 | Q18: C0015 | R18: Female | S18: 43 | T18: Cleveland
B19: Call_7286 | C19: C0010 | D19: 176 | E19: R05 | F19: 44931 | G19: 24 | H19: 4.8 | I19: =IF(MONTH(calls[[#This Row],[Date of Call]])<=6, YEAR(calls[[#This Row],[Date of Call]]), YEAR(calls[[#This Row],[Date of Call]])+1) -> 2023 | J19: =TEXT(calls[[#This Row],[Date of Call]],"DDDD") -> Thursday | K19: {=_xlfn.IFS(calls[[#This Row],[Duration]]<=10,"Under 10 mins", calls[[#This Row],[Duration]]<=30, "10 to 30 mins", calls[[#This Row],[Duration]]<=60, "30 to 60 mins", calls[[#This Row],[Duration]]<=120, "1 to 2 hours", TRUE, "More than 2 hours")} -> More than 2 hours | L19: =ROUND(calls[[#This Row],[Satisfaction Rating]],0) -> 5
B20: Call_7287 | C20: C0010 | D20: 99 | E20: R01 | F20: 44931 | G20: 195 | H20: 3.9 | I20: =IF(MONTH(calls[[#This Row],[Date of Call]])<=6, YEAR(calls[[#This Row],[Date of Call]]), YEAR(calls[[#This Row],[Date of Call]])+1) -> 2023 | J20: =TEXT(calls[[#This Row],[Date of Call]],"DDDD") -> Thursday | K20: {=_xlfn.IFS(calls[[#This Row],[Duration]]<=10,"Under 10 mins", calls[[#This Row],[Duration]]<=30, "10 to 30 mins", calls[[#This Row],[Duration]]<=60, "30 to 60 mins", calls[[#This Row],[Duration]]<=120, "1 to 2 hours", TRUE, "More than 2 hours")} -> 1 to 2 hours | L20: =ROUND(calls[[#This Row],[Satisfaction Rating]],0) -> 4
B21: Call_7288 | C21: C0009 | D21: 28 | E21: R03 | F21: 44931 | G21: 28 | H21: 3.8 | I21: =IF(MONTH(calls[[#This Row],[Date of Call]])<=6, YEAR(calls[[#This Row],[Date of Call]]), YEAR(calls[[#This Row],[Date of Call]])+1) -> 2023 | J21: =TEXT(calls[[#This Row],[Date of Call]],"DDDD") -> Thursday | K21: {=_xlfn.IFS(calls[[#This Row],[Duration]]<=10,"Under 10 mins", calls[[#This Row],[Duration]]<=30, "10 to 30 mins", calls[[#This Row],[Duration]]<=60, "30 to 60 mins", calls[[#This Row],[Duration]]<=120, "1 to 2 hours", TRUE, "More than 2 hours")} -> 10 to 30 mins | L21: =ROUND(calls[[#This Row],[Satisfaction Rating]],0) -> 4
B22: Call_7289 | C22: C0007 | D22: 54 | E22: R02 | F22: 44931 | G22: 170 | H22: 4.3 | I22: =IF(MONTH(calls[[#This Row],[Date of Call]])<=6, YEAR(calls[[#This Row],[Date of Call]]), YEAR(calls[[#This Row],[Date of Call]])+1) -> 2023 | J22: =TEXT(calls[[#This Row],[Date of Call]],"DDDD") -> Thursday | K22: {=_xlfn.IFS(calls[[#This Row],[Duration]]<=10,"Under 10 mins", calls[[#This Row],[Duration]]<=30, "10 to 30 mins", calls[[#This Row],[Duration]]<=60, "30 to 60 mins", calls[[#This Row],[Duration]]<=120, "1 to 2 hours", TRUE, "More than 2 hours")} -> 30 to 60 mins | L22: =ROUND(calls[[#This Row],[Satisfaction Rating]],0) -> 4
B23: Call_7290 | C23: C0006 | D23: 48 | E23: R05 | F23: 44932 | G23: 30 | H23: 4.4 | I23: =IF(MONTH(calls[[#This Row],[Date of Call]])<=6, YEAR(calls[[#This Row],[Date of Call]]), YEAR(calls[[#This Row],[Date of Call]])+1) -> 2023 | J23: =TEXT(calls[[#This Row],[Date of Call]],"DDDD") -> Friday | K23: {=_xlfn.IFS(calls[[#This Row],[Duration]]<=10,"Under 10 mins", calls[[#This Row],[Duration]]<=30, "10 to 30 mins", calls[[#This Row],[Duration]]<=60, "30 to 60 mins", calls[[#This Row],[Duration]]<=120, "1 to 2 hours", TRUE, "More than 2 hours")} -> 30 to 60 mins | L23: =ROUND(calls[[#This Row],[Satisfaction Rating]],0) -> 4
B24: Call_7291 | C24: C0004 | D24: 128 | E24: R05 | F24: 44932 | G24: 72 | H24: 5 | I24: =IF(MONTH(calls[[#This Row],[Date of Call]])<=6, YEAR(calls[[#This Row],[Date of Call]]), YEAR(calls[[#This Row],[Date of Call]])+1) -> 2023 | J24: =TEXT(calls[[#This Row],[Date of Call]],"DDDD") -> Friday | K24: {=_xlfn.IFS(calls[[#This Row],[Duration]]<=10,"Under 10 mins", calls[[#This Row],[Duration]]<=30, "10 to 30 mins", calls[[#This Row],[Duration]]<=60, "30 to 60 mins", calls[[#This Row],[Duration]]<=120, "1 to 2 hours", TRUE, "More than 2 hours")} -> More than 2 hours | L24: =ROUND(calls[[#This Row],[Satisfaction Rating]],0) -> 5
B25: Call_7292 | C25: C0004 | D25: 38 | E25: R04 | F25: 44933 | G25: 92 | H25: 4.9 | I25: =IF(MONTH(calls[[#This Row],[Date of Call]])<=6, YEAR(calls[[#This Row],[Date of Call]]), YEAR(calls[[#This Row],[Date of Call]])+1) -> 2023 | J25: =TEXT(calls[[#This Row],[Date of Call]],"DDDD") -> Saturday | K25: {=_xlfn.IFS(calls[[#This Row],[Duration]]<=10,"Under 10 mins", calls[[#This Row],[Duration]]<=30, "10 to 30 mins", calls[[#This Row],[Duration]]<=60, "30 to 60 mins", calls[[#This Row],[Duration]]<=120, "1 to 2 hours", TRUE, "More than 2 hours")} -> 30 to 60 mins | L25: =ROUND(calls[[#This Row],[Satisfaction Rating]],0) -> 5
B26: Call_7293 | C26: C0003 | D26: 67 | E26: R04 | F26: 44934 | G26: 165 | H26: 4.5 | I26: =IF(MONTH(calls[[#This Row],[Date of Call]])<=6, YEAR(calls[[#This Row],[Date of Call]]), YEAR(calls[[#This Row],[Date of Call]])+1) -> 2023 | J26: =TEXT(calls[[#This Row],[Date of Call]],"DDDD") -> Sunday | K26: {=_xlfn.IFS(calls[[#This Row],[Duration]]<=10,"Under 10 mins", calls[[#This Row],[Duration]]<=30, "10 to 30 mins", calls[[#This Row],[Duration]]<=60, "30 to 60 mins", calls[[#This Row],[Duration]]<=120, "1 to 2 hours", TRUE, "More than 2 hours")} -> 1 to 2 hours | L26: =ROUND(calls[[#This Row],[Satisfaction Rating]],0) -> 5
B27: Call_7294 | C27: C0015 | D27: 58 | E27: R02 | F27: 44934 | G27: 140 | H27: 2.1 | I27: =IF(MONTH(calls[[#This Row],[Date of Call]])<=6, YEAR(calls[[#This Row],[Date of Call]]), YEAR(calls[[#This Row],[Date of Call]])+1) -> 2023 | J27: =TEXT(calls[[#This Row],[Date of Call]],"DDDD") -> Sunday | K27: {=_xlfn.IFS(calls[[#This Row],[Duration]]<=10,"Under 10 mins", calls[[#This Row],[Duration]]<=30, "10 to 30 mins", calls[[#This Row],[Duration]]<=60, "30 to 60 mins", calls[[#This Row],[Duration]]<=120, "1 to 2 hours", TRUE, "More than 2 hours")} -> 30 to 60 mins | L27: =ROUND(calls[[#This Row],[Satisfaction Rating]],0) -> 2
B28: Call_7295 | C28: C0010 | D28: 54 | E28: R01 | F28: 44934 | G28: 111 | H28: 3.3 | I28: =IF(MONTH(calls[[#This Row],[Date of Call]])<=6, YEAR(calls[[#This Row],[Date of Call]]), YEAR(calls[[#This Row],[Date of Call]])+1) -> 2023 | J28: =TEXT(calls[[#This Row],[Date of Call]],"DDDD") -> Sunday | K28: {=_xlfn.IFS(calls[[#This Row],[Duration]]<=10,"Under 10 mins", calls[[#This Row],[Duration]]<=30, "10 to 30 mins", calls[[#This Row],[Duration]]<=60, "30 to 60 mins", calls[[#This Row],[Duration]]<=120, "1 to 2 hours", TRUE, "More than 2 hours")} -> 30 to 60 mins | L28: =ROUND(calls[[#This Row],[Satisfaction Rating]],0) -> 3
B29: Call_7296 | C29: C0012 | D29: 28 | E29: R05 | F29: 44935 | G29: 63 | H29: 4.1 | I29: =IF(MONTH(calls[[#This Row],[Date of Call]])<=6, YEAR(calls[[#This Row],[Date of Call]]), YEAR(calls[[#This Row],[Date of Call]])+1) -> 2023 | J29: =TEXT(calls[[#This Row],[Date of Call]],"DDDD") -> Monday | K29: {=_xlfn.IFS(calls[[#This Row],[Duration]]<=10,"Under 10 mins", calls[[#This Row],[Duration]]<=30, "10 to 30 mins", calls[[#This Row],[Duration]]<=60, "30 to 60 mins", calls[[#This Row],[Duration]]<=120, "1 to 2 hours", TRUE, "More than 2 hours")} -> 10 to 30 mins | L29: =ROUND(calls[[#This Row],[Satisfaction Rating]],0) -> 4
B30: Call_7297 | C30: C0002 | D30: 73 | E30: R05 | F30: 44935 | G30: 80 | H30: 4.2 | I30: =IF(MONTH(calls[[#This Row],[Date of Call]])<=6, YEAR(calls[[#This Row],[Date of Call]]), YEAR(calls[[#This Row],[Date of Call]])+1) -> 2023 | J30: =TEXT(calls[[#This Row],[Date of Call]],"DDDD") -> Monday | K30: {=_xlfn.IFS(calls[[#This Row],[Duration]]<=10,"Under 10 mins", calls[[#This Row],[Duration]]<=30, "10 to 30 mins", calls[[#This Row],[Duration]]<=60, "30 to 60 mins", calls[[#This Row],[Duration]]<=120, "1 to 2 hours", TRUE, "More than 2 hours")} -> 1 to 2 hours | L30: =ROUND(calls[[#This Row],[Satisfaction Rating]],0) -> 4
... B1003: Call_8270 | C1003: C0009 | D1003: 114 | E1003: R01 | F1003: 45291 | G1003: 40 | H1003: 3.9 | I1003: =IF(MONTH(calls[[#This Row],[Date of Call]])<=6, YEAR(calls[[#This Row],[Date of Call]]), YEAR(calls[[#This Row],[Date of Call]])+1) -> 2024 | J1003: =TEXT(calls[[#This Row],[Date of Call]],"DDDD") -> Sunday | K1003: {=_xlfn.IFS(calls[[#This Row],[Duration]]<=10,"Under 10 mins", calls[[#This Row],[Duration]]<=30, "10 to 30 mins", calls[[#This Row],[Duration]]<=60, "30 to 60 mins", calls[[#This Row],[Duration]]<=120, "1 to 2 hours", TRUE, "More than 2 hours")} -> 1 to 2 hours | L1003: =ROUND(calls[[#This Row],[Satisfaction Rating]],0) -> 4

Sheet Assets
E2: Rep ID | F2: Rep Image
E3: R01 | F3: #VALUE!
E4: R02 | F4: #VALUE!
E5: R03 | F5: #VALUE!
E6: R04 | F6: #VALUE!
E7: R05 | F7: #VALUE!

Sheet Customer Report
C1: CALL CENTER REPORT - 2023
Q18: =Pivots!B81 -> R01 | R18: =Pivots!C81 -> R02 | S18: =Pivots!D81 -> R03 | T18: =Pivots!E81 -> R04 | U18: =Pivots!F81 -> R05 | V18: TOTAL
P19: =IF(Pivots!A82="", "", Pivots!A82) -> Cincinnati | Q19: =IF(Pivots!B82="", "", Pivots!B82) | R19: =IF(Pivots!C82="", "", Pivots!C82) | S19: =IF(Pivots!D82="", "", Pivots!D82) | T19: =IF(Pivots!E82="", "", Pivots!E82) | U19: =IF(Pivots!F82="", "", Pivots!F82) | V19: =IF(Pivots!G82="", "", Pivots!G82)
P20: =IF(Pivots!A83="", "", Pivots!A83) -> C0003 | Q20: =IF(Pivots!B83="", "", Pivots!B83) -> 891 | R20: =IF(Pivots!C83="", "", Pivots!C83) -> 1332 | S20: =IF(Pivots!D83="", "", Pivots!D83) -> 1282 | T20: =IF(Pivots!E83="", "", Pivots!E83) -> 739 | U20: =IF(Pivots!F83="", "", Pivots!F83) -> 560 | V20: =IF(Pivots!G83="", "", Pivots!G83) -> 4804
P21: =IF(Pivots!A84="", "", Pivots!A84) -> C0004 | Q21: =IF(Pivots!B84="", "", Pivots!B84) -> 1991 | R21: =IF(Pivots!C84="", "", Pivots!C84) -> 1886 | S21: =IF(Pivots!D84="", "", Pivots!D84) -> 1206 | T21: =IF(Pivots!E84="", "", Pivots!E84) -> 884 | U21: =IF(Pivots!F84="", "", Pivots!F84) -> 1722 | V21: =IF(Pivots!G84="", "", Pivots!G84) -> 7689
P22: =IF(Pivots!A85="", "", Pivots!A85) -> C0011 | Q22: =IF(Pivots!B85="", "", Pivots!B85) -> 1163 | R22: =IF(Pivots!C85="", "", Pivots!C85) -> 1180 | S22: =IF(Pivots!D85="", "", Pivots!D85) -> 1616 | T22: =IF(Pivots!E85="", "", Pivots!E85) -> 1043 | U22: =IF(Pivots!F85="", "", Pivots!F85) -> 1747 | V22: =IF(Pivots!G85="", "", Pivots!G85) -> 6749
P23: =IF(Pivots!A86="", "", Pivots!A86) -> C0012 | Q23: =IF(Pivots!B86="", "", Pivots!B86) -> 1438 | R23: =IF(Pivots!C86="", "", Pivots!C86) -> 1616 | S23: =IF(Pivots!D86="", "", Pivots!D86) -> 866 | T23: =IF(Pivots!E86="", "", Pivots!E86) -> 829 | U23: =IF(Pivots!F86="", "", Pivots!F86) -> 2070 | V23: =IF(Pivots!G86="", "", Pivots!G86) -> 6819
P24: =IF(Pivots!A87="", "", Pivots!A87) -> Cleveland | Q24: =IF(Pivots!B87="", "", Pivots!B87) | R24: =IF(Pivots!C87="", "", Pivots!C87) | S24: =IF(Pivots!D87="", "", Pivots!D87) | T24: =IF(Pivots!E87="", "", Pivots!E87) | U24: =IF(Pivots!F87="", "", Pivots!F87) | V24: =IF(Pivots!G87="", "", Pivots!G87)
P25: =IF(Pivots!A88="", "", Pivots!A88) -> C0002 | Q25: =IF(Pivots!B88="", "", Pivots!B88) -> 1233 | R25: =IF(Pivots!C88="", "", Pivots!C88) -> 223 | S25: =IF(Pivots!D88="", "", Pivots!D88) -> 1680 | T25: =IF(Pivots!E88="", "", Pivots!E88) -> 990 | U25: =IF(Pivots!F88="", "", Pivots!F88) -> 1508 | V25: =IF(Pivots!G88="", "", Pivots!G88) -> 5634
P26: =IF(Pivots!A89="", "", Pivots!A89) -> C0007 | Q26: =IF(Pivots!B89="", "", Pivots!B89) -> 1598 | R26: =IF(Pivots!C89="", "", Pivots!C89) -> 1907 | S26: =IF(Pivots!D89="", "", Pivots!D89) -> 869 | T26: =IF(Pivots!E89="", "", Pivots!E89) -> 1426 | U26: =IF(Pivots!F89="", "", Pivots!F89) -> 1416 | V26: =IF(Pivots!G89="", "", Pivots!G89) -> 7216
P27: =IF(Pivots!A90="", "", Pivots!A90) -> C0008 | Q27: =IF(Pivots!B90="", "", Pivots!B90) -> 900 | R27: =IF(Pivots!C90="", "", Pivots!C90) -> 1016 | S27: =IF(Pivots!D90="", "", Pivots!D90) -> 960 | T27: =IF(Pivots!E90="", "", Pivots!E90) -> 940 | U27: =IF(Pivots!F90="", "", Pivots!F90) -> 1193 | V27: =IF(Pivots!G90="", "", Pivots!G90) -> 5009
P28: =IF(Pivots!A91="", "", Pivots!A91) -> C0010 | Q28: =IF(Pivots!B91="", "", Pivots!B91) -> 900 | R28: =IF(Pivots!C91="", "", Pivots!C91) -> 1470 | S28: =IF(Pivots!D91="", "", Pivots!D91) -> 1617 | T28: =IF(Pivots!E91="", "", Pivots!E91) -> 1314 | U28: =IF(Pivots!F91="", "", Pivots!F91) -> 941 | V28: =IF(Pivots!G91="", "", Pivots!G91) -> 6242
P29: =IF(Pivots!A92="", "", Pivots!A92) -> C0013 | Q29: =IF(Pivots!B92="", "", Pivots!B92) -> 1255 | R29: =IF(Pivots!C92="", "", Pivots!C92) -> 516 | S29: =IF(Pivots!D92="", "", Pivots!D92) -> 1874 | T29: =IF(Pivots!E92="", "", Pivots!E92) -> 1863 | U29: =IF(Pivots!F92="", "", Pivots!F92) -> 1722 | V29: =IF(Pivots!G92="", "", Pivots!G92) -> 7230
P30: =IF(Pivots!A93="", "", Pivots!A93) -> C0015 | Q30: =IF(Pivots!B93="", "", Pivots!B93) -> 1138 | R30: =IF(Pivots!C93="", "", Pivots!C93) -> 1898 | S30: =IF(Pivots!D93="", "", Pivots!D93) -> 1482 | T30: =IF(Pivots!E93="", "", Pivots!E93) -> 846 | U30: =IF(Pivots!F93="", "", Pivots!F93) -> 1154 | V30: =IF(Pivots!G93="", "", Pivots!G93) -> 6518
... P36: =IF(Pivots!A99="", "", Pivots!A99) -> C0014 | Q36: =IF(Pivots!B99="", "", Pivots!B99) -> 1362 | R36: =IF(Pivots!C99="", "", Pivots!C99) -> 1363 | S36: =IF(Pivots!D99="", "", Pivots!D99) -> 1152 | T36: =IF(Pivots!E99="", "", Pivots!E99) -> 777 | U36: =IF(Pivots!F99="", "", Pivots!F99) -> 750 | V36: =IF(Pivots!G99="", "", Pivots!G99) -> 5404
